<?xml version="1.0"?>
<robot name="ogv_body">

<xacro:macro name="ogv_body" xmlns:xacro="http://ros.org/wiki/xacro">

  <material name="blue">
    <color rgba="0 0 0.8 1"/>
  </material>
  <material name="black">
    <color rgba="0 0 0 1"/>
  </material>
  <material name="white">
    <color rgba="1 1 1 1"/>
  </material>
  <material name="red">
    <color rgba="1 0 0 1"/>
  </material>

  <link name="base_link">
  </link>

  <link name="main_frame">
    <visual>
      <geometry>
        <box size="0.355 0.330 0.072"/>
      </geometry>
      <origin rpy="0 0 0" xyz="0 0 0.036"/>
      <material name="black"/>
    </visual>
    <collision>
      <geometry>
        <box size="0.355 0.330 0.072"/>
      </geometry>
    </collision>
    <inertial>
      <mass value="4.07"/>
      <inertia ixx="0.426" ixy="0.0" ixz="0.0" iyy="0.496" iyz="0.0" izz="0.91"/>
    </inertial>
  </link>

  <joint name="base_to_main_frame" type="fixed">
    <parent link="base_link"/>
    <child link="main_frame"/>
    <origin xyz="0 0 0"/>
  </joint>

  <!-- LIDAR  -->

  <link name="base_laser_link">
    <visual>
      <geometry>
        <cylinder length="0.07" radius="0.035"/>
      </geometry>
      <origin rpy="0 0 0" xyz="0 0 -0.027"/>
      <material name="white"/>
    </visual>
    <collision>
      <geometry>
        <cylinder length="0.07" radius="0.035"/>
      </geometry>
    </collision>
    <inertial>
      <mass value="0.22"/>
      <inertia ixx="0.000157" ixy="0.0" ixz="0.0" iyy="0.000157" iyz="0.0" izz="0.000135"/>
    </inertial>
  </link>

  <joint name="base_to_laser" type="fixed">
    <parent link="base_link"/>
    <child link="base_laser_link"/>
    <origin xyz="0.144 0 0.134"/>
  </joint>

  <link name="laser_frame" />

  <joint name="base_laser_rotated" type="fixed">
    <parent link="base_laser_link"/>
    <child link="laser_frame"/>
    <axis xyz="0 0 1"/>
    <origin xyz="0 0 0" rpy="0 0 3.14"/>
  </joint>

  <!-- REALSENSE CAMERA -->
  <link name="realsense_base_link">
  </link>

  <joint name="base_to_realsense" type="fixed">
    <parent link="base_link"/>
    <child link="realsense_base_link"/>
    <origin xyz="0.196 0 -0.03"/>
  </joint>

  <!-- WHEELS AND SERVOS -->

  <link name="right_front_servo_holder">
    <visual>
      <geometry>
        <box size="0.05 0.095 0.03"/>
      </geometry>
      <origin rpy="0 0 0" xyz="0.025 -0.0475 0.015"/>
      <material name="white"/>
    </visual>
    <collision>
      <geometry>
        <box size="0.05 0.095 0.03"/>
      </geometry>
    </collision>
    <inertial>
      <mass value="0.151"/>
      <inertia ixx="0.000125" ixy="0.0" ixz="0.0" iyy="0.000145" iyz="0.0" izz="0.000043"/>
    </inertial>
  </link>

  <joint name="base_to_right_front_servo_holder" type="fixed">
    <parent link="base_link"/>
    <child link="right_front_servo_holder"/>
    <origin xyz="0.179 -0.14 -0.005"/>
  </joint>

  <link name="left_front_servo_holder">
    <visual>
      <geometry>
        <box size="0.05 0.095 0.03"/>
      </geometry>
      <origin rpy="0 0 0" xyz="0.025 0.0475 0.015"/>
      <material name="white"/>
    </visual>
    <collision>
      <geometry>
        <box size="0.05 0.095 0.03"/>
      </geometry>
    </collision>
    <inertial>
      <mass value="0.151"/>
      <inertia ixx="0.000125" ixy="0.0" ixz="0.0" iyy="0.000145" iyz="0.0" izz="0.000043"/>
    </inertial>
  </link>

  <joint name="base_to_left_front_servo_holder" type="fixed">
    <parent link="base_link"/>
    <child link="left_front_servo_holder"/>
    <origin xyz="0.179 0.14 -0.005"/>
  </joint>

  <link name="left_back_servo_holder">
    <visual>
      <geometry>
        <box size="0.05 0.095 0.03"/>
      </geometry>
      <origin rpy="0 0 0" xyz="-0.025 0.0475 0.015"/>
      <material name="white"/>
    </visual>
    <collision>
      <geometry>
        <box size="0.05 0.095 0.03"/>
      </geometry>
    </collision>
    <inertial>
      <mass value="0.151"/>
      <inertia ixx="0.000125" ixy="0.0" ixz="0.0" iyy="0.000145" iyz="0.0" izz="0.000043"/>
    </inertial>
  </link>

  <joint name="base_to_left_back_servo_holder" type="fixed">
    <parent link="base_link"/>
    <child link="left_back_servo_holder"/>
    <origin xyz="-0.179 0.14 -0.005"/>
  </joint>

  <link name="right_back_servo_holder">
    <visual>
      <geometry>
        <box size="0.05 0.095 0.03"/>
      </geometry>
      <origin rpy="0 0 0" xyz="-0.025 -0.0475 0.015"/>
      <material name="white"/>
    </visual>
    <collision>
      <geometry>
        <box size="0.05 0.095 0.03"/>
      </geometry>
    </collision>
    <inertial>
      <mass value="0.151"/>
      <inertia ixx="0.000125" ixy="0.0" ixz="0.0" iyy="0.000145" iyz="0.0" izz="0.000043"/>
    </inertial>
  </link>

  <joint name="base_to_right_back_servo_holder" type="fixed">
    <parent link="base_link"/>
    <child link="right_back_servo_holder"/>
    <origin xyz="-0.179 -0.14 -0.005"/>
  </joint>

  <link name="right_front_servo">
    <visual>
      <geometry>
        <cylinder length="0.12" radius="0.0125"/>
      </geometry>
      <origin rpy="0 0 0 " xyz="0 0 -0.06"/>
    </visual>
    <collision>
      <geometry>
        <cylinder length="0.12" radius="0.0125"/>
      </geometry>
    </collision>
    <inertial>
      <mass value="0.23"/>
      <inertia ixx="0.000285" ixy="0.0" ixz="0.0" iyy="0.000285" iyz="0.0" izz="0.000018"/>
    </inertial>
  </link>

  <joint name="right_front_servo_to_holder" type="revolute">
    <axis xyz="0 0 1"/>
    <limit effort="1000.0" lower="-1.5708" upper="1.5708" velocity="0.1"/>
    <origin rpy="0 0 -3.1426" xyz="0.025 -0.07 0.03"/>
    <parent link="right_front_servo_holder"/>
    <child link="right_front_servo"/>
  </joint>

  <link name="left_front_servo">
    <visual>
      <geometry>
        <cylinder length="0.12" radius="0.0125"/>
      </geometry>
      <origin rpy="0 0 0 " xyz="0 0 -0.06"/>
    </visual>
    <collision>
      <geometry>
        <cylinder length="0.12" radius="0.0125"/>
      </geometry>
    </collision>
    <inertial>
      <mass value="0.23"/>
      <inertia ixx="0.000285" ixy="0.0" ixz="0.0" iyy="0.000285" iyz="0.0" izz="0.000018"/>
    </inertial>
  </link>

  <joint name="left_front_servo_to_holder" type="revolute">
    <axis xyz="0 0 1"/>
    <limit effort="1000.0" lower="-1.5708" upper="1.5708" velocity="0.1"/>
    <origin rpy="0 0 0" xyz="0.025 0.07 0.03"/>
    <parent link="left_front_servo_holder"/>
    <child link="left_front_servo"/>
  </joint>

  <link name="left_back_servo">
    <visual>
      <geometry>
        <cylinder length="0.12" radius="0.0125"/>
      </geometry>
      <origin rpy="0 0 0 " xyz="0 0 -0.06"/>
    </visual>
    <collision>
      <geometry>
        <cylinder length="0.12" radius="0.0125"/>
      </geometry>
    </collision>
    <inertial>
      <mass value="0.23"/>
      <inertia ixx="0.000285" ixy="0.0" ixz="0.0" iyy="0.000285" iyz="0.0" izz="0.000018"/>
    </inertial>
  </link>

  <joint name="left_back_servo_to_holder" type="revolute">
    <axis xyz="0 0 1"/>
    <limit effort="1000.0" lower="-1.5708" upper="1.5708" velocity="0.1"/>
    <origin rpy="0 0 0" xyz="-0.025 0.07 0.03"/>
    <parent link="left_back_servo_holder"/>
    <child link="left_back_servo"/>
  </joint>

  <link name="right_back_servo">
    <visual>
      <geometry>
        <cylinder length="0.12" radius="0.0125"/>
      </geometry>
      <origin rpy="0 0 0 " xyz="0 0 -0.06"/>
    </visual>
    <collision>
      <geometry>
        <cylinder length="0.12" radius="0.0125"/>
      </geometry>
    </collision>
    <inertial>
      <mass value="0.23"/>
      <inertia ixx="0.000285" ixy="0.0" ixz="0.0" iyy="0.000285" iyz="0.0" izz="0.000018"/>
    </inertial>
  </link>

  <joint name="right_back_servo_to_holder" type="revolute">
    <axis xyz="0 0 1"/>
    <limit effort="1000.0" lower="-1.5708" upper="1.5708" velocity="0.1"/>
    <origin rpy="0 0 3.1426" xyz="-0.025 -0.07 0.03"/>
    <parent link="right_back_servo_holder"/>
    <child link="right_back_servo"/>
  </joint>

  <link name="right_front_wheel">
    <visual>
      <origin rpy="1.57075 0 0" xyz="0 0 0"/>
      <geometry>
        <cylinder length="0.06" radius="0.06"/>
      </geometry>
      <material name="black"/>
      <origin rpy="0 0 0" xyz="0 0 0"/>
    </visual>
    <collision>
      <geometry>
        <cylinder length="0.06" radius="0.06"/>
      </geometry>
    </collision>
    <inertial>
      <mass value="0.17"/>
      <inertia ixx="0.000204" ixy="0.0" ixz="0.0" iyy="0.000306" iyz="0.0" izz="0.000204"/>
    </inertial>
  </link>

  <joint name="right_front_wheel_joint" type="continuous">
    <axis rpy="0 0 0" xyz="0 1 0"/>
    <parent link="right_front_servo"/>
    <child link="right_front_wheel"/>
    <origin rpy="0 0 0" xyz="0 0 -0.12"/>
  </joint>

  <link name="left_front_wheel">
    <visual>
      <origin rpy="1.57075 0 0" xyz="0 0 0"/>
      <geometry>
        <cylinder length="0.06" radius="0.06"/>
      </geometry>
      <material name="black"/>
      <origin rpy="0 0 0" xyz="0 0 0"/>
    </visual>
     <collision>
      <geometry>
        <cylinder length="0.06" radius="0.06"/>
      </geometry>
    </collision>
    <inertial>
      <mass value="0.17"/>
      <inertia ixx="0.000204" ixy="0.0" ixz="0.0" iyy="0.000306" iyz="0.0" izz="0.000204"/>
    </inertial>
  </link>

  <joint name="left_front_wheel_joint" type="continuous">
    <axis rpy="0 0 0" xyz="0 1 0"/>
    <parent link="left_front_servo"/>
    <child link="left_front_wheel"/>
    <origin rpy="0 0 0" xyz="0 0 -0.12"/>
  </joint>

  <link name="left_back_wheel">
    <visual>
      <origin rpy="1.57075 0 0" xyz="0 0 0"/>
      <geometry>
        <cylinder length="0.06" radius="0.06"/>
      </geometry>
      <material name="black"/>
      <origin rpy="0 0 0" xyz="0 0 0"/>
    </visual>
     <collision>
      <geometry>
        <cylinder length="0.06" radius="0.06"/>
      </geometry>
    </collision>
    <inertial>
      <mass value="0.17"/>
      <inertia ixx="0.000204" ixy="0.0" ixz="0.0" iyy="0.000306" iyz="0.0" izz="0.000204"/>
    </inertial>
  </link>

  <joint name="left_back_wheel_joint" type="continuous">
    <axis rpy="0 0 0" xyz="0 1 0"/>
    <parent link="left_back_servo"/>
    <child link="left_back_wheel"/>
    <origin rpy="0 0 0" xyz="0 0 -0.12"/>
  </joint>

  <link name="right_back_wheel">
    <visual>
      <origin rpy="1.57075 0 0" xyz="0 0 0"/>
      <geometry>
        <cylinder length="0.06" radius="0.06"/>
      </geometry>
      <material name="black"/>
      <origin rpy="0 0 0" xyz="0 0 0"/>
    </visual>
     <collision>
      <geometry>
        <cylinder length="0.06" radius="0.06"/>
      </geometry>
    </collision>
    <inertial>
      <mass value="0.17"/>
      <inertia ixx="0.000204" ixy="0.0" ixz="0.0" iyy="0.000306" iyz="0.0" izz="0.000204"/>
    </inertial>
  </link>

  <joint name="right_back_wheel_joint" type="continuous">
    <axis rpy="0 0 0" xyz="0 1 0"/>
    <parent link="right_back_servo"/>
    <child link="right_back_wheel"/>
    <origin rpy="0 0 0" xyz="0 0 -0.12"/>
  </joint>

  <!-- FLOOR FRAME -->

  <link name="floor_frame">
  </link>

  <joint name="base_link_to_floor_joint" type="fixed">
    <parent link="base_link"/>
    <child link="floor_frame"/>
    <origin rpy="0 0 0" xyz="0 0 -0.164"/>
  </joint>

  </xacro:macro>
</robot>
